Traceback (most recent call last):
  File "<frozen runpy>", line 198, in _run_module_as_main
  File "<frozen runpy>", line 88, in _run_code
  File "/Users/danielennis/ai-apps/rate limit message/.venv/lib/python3.12/site-packages/llama_stack/distribution/server/server.py", line 592, in <module>
    main()
  File "/Users/danielennis/ai-apps/rate limit message/.venv/lib/python3.12/site-packages/llama_stack/distribution/server/server.py", line 429, in main
    config = StackRunConfig(**config)
             ^^^^^^^^^^^^^^^^^^^^^^^^
  File "/Users/danielennis/ai-apps/rate limit message/.venv/lib/python3.12/site-packages/pydantic/main.py", line 253, in __init__
    validated_self = self.__pydantic_validator__.validate_python(data, self_instance=self)
                     ^^^^^^^^^^^^^^^^^^^^^^^^^^^^^^^^^^^^^^^^^^^^^^^^^^^^^^^^^^^^^^^^^^^^^
pydantic_core._pydantic_core.ValidationError: 1 validation error for StackRunConfig
image_name
  Field required [type=missing, input_value={'apis': ['inference', 's...calhost', 'port': 8321}}, input_type=dict]
    For further information visit https://errors.pydantic.dev/2.11/v/missing
